{
  "errorMessage": "query_using_secrets: Execption encountered executing query ERROR:  relation \"role_specific_priv_tables\" does not exist\nLINE 2:         select*from role_specific_priv_tables where scanid =...\n                            ^\n.",
  "errorType": "ValueError",
  "requestId": "68caaadf-43bd-4a25-8362-425ef4c5f164",
  "stackTrace": [
    "  File \"/var/task/lambda_function.py\", line 1849, in lambda_handler\n    generate_csv_and_pdf_reports_for_the_drift_tables(reporting_db_secrets_client, reporting_db_secret_arn, table_names_list, scan_id)\n",
    "  File \"/var/task/lambda_function.py\", line 811, in generate_csv_and_pdf_reports_for_the_drift_tables\n    result = pgs.run_query_using_secrets(secrets_client, reporting_db_secret_arn, sql)\n",
    "  File \"/opt/python/lib/python3.9/site-packages/postgres_utils.py\", line 416, in run_query_using_secrets\n    raise ValueError(\"query_using_secrets: Execption encountered executing query %s.\" % e)\n"
  ]
}
